# 2024.04.02 TIL

## 📚 try..catch & async await

### 🚨 try...catch

실수나 예상치 못한 사용자 입력, 잘못된 서버 응답등의 이유로 에러가 발생하면 스크립트는 중단되고 콘솔에 에러가 출력된다.

#### 이럴 때 try...catch 문법을 사용하면 스크립트가 죽는것을 발생하고 에러를 잡아서(catch) 더 합당한 무언가를 할 수 있다.

```js
try {
  // 코드...
} catch (err) {
  // 에러 핸들링
}
```

먼저 try 블록 안의 코드가 실행되고, 에러가 없다면 try 안의 마지막 줄까지 실행되고, catch 블록은 건너뛴다.

만약 에러가 있다면, try 안 코드의 실행이 중단되고, catch(err) 블록으로 제어 흐름이 넘어간다. 변수 err는 무슨 일이 일어났는지에 대한 설명이 담긴 에러 객체를 포함한다.

#### 이렇게 try 블록 안에서 에러가 발생해도 catch에서 에러를 처리하기 때문에 스크립트는 죽지 않는다.

---

### 💡 try...catch 사용 예시

```js
// 1과 3을 보여준다
try {
  alert("try 블록 시작"); // (1) <--

  lalala; // 에러, 변수가 정의되지 않음!

  alert("try 블록 끝(절대 도달하지 않음)"); // (2)
} catch (err) {
  alert(`에러가 발생했습니다!`); // (3) <--
}
```

추가적으로 try...catch는 오직 런타임 에러에만 동작한다.

---

#### 🚨try...catch는 동기적으로 동작한다.

setTimeout처럼 스케줄된 코드에서 발생한 예외는 try...catch에서 잡아낼 수 없다.

setTimeout에 넘겨진 익명 함수는 자바스크립트 엔진이 try catch를 떠난 다음에야 실행되기 때문에 스케줄 된 함수 내부의 예외를 잡으려면, try...catch를 반드시 함수 내부에 구현해야 한다.

---

### ⚡️ axios.get은 비동기 함수이므로 그 내부에서 발생한 오류는 .catch() 또는 .then()함수 내에서 처리해야 한다.

따라서

```js
const getSearchHistory = () => {
  if (accessToken) {
    try {
      axios
        .get("/history", {
          headers: { Authorization: accessToken },
        })
        .then(async (res: any) => {
          console.log(res.status);
          if (res.data.result.length > 0) {
            console.log("res.data.result:", res.data.result);
            setSearchHistory(res.data.result);
          } else {
            setSearchHistory(null);
            setIsFocused(false);
          }
        })
        .then(() => {
          console.log("회원 히스토리 가져오기 끝!", searchHistory);
        });
    } catch (error) {
      // a토큰 재발급 후 재시도
      console.log("에러뜸");
    }
  } else {
    let searchHistory: any = localStorage.getItem("searchHistory");
    searchHistory = JSON.parse(searchHistory);
    setSearchHistory(searchHistory);
    console.log("비회원 히스토리 가져오기 끝!");
  }
};
```

이게 아니라

```js
axios
  .get("/history", {
    headers: { Authorization: accessToken },
  })
  .then(async (res: any) => {
    console.log(res.status);
    if (res.data.result.length > 0) {
      console.log("res.data.result:", res.data.result);
      setSearchHistory(res.data.result);
    } else {
      setSearchHistory(null);
      setIsFocused(false);
    }
  })
  .then(() => {
    console.log("회원 히스토리 가져오기 끝!", searchHistory);
  })
  .catch((error) => {
    console.log("에러뜸:", error); // 에러 처리 추가
  });
```

이렇게 코드가 변경돼야함.

#### axios는 then과 catch를 따로 가지고 있는데 이 둘은 Promise 기반으로 동작하며 http 요청이 성공적으로 응답되면 then이 호출되고, 에러가 발생하면 catch가 호출된다.

---
